<?xml version="1.0" encoding="UTF-8"?>
<robot xmlns:xacro="http://www.ros.org/wiki/xacro">

  <!-- Chassis link -->
  <joint name="base_joint" type="fixed">
    <parent link="base_footprint" />
    <child link="base_link" />
    <origin xyz="0 0 0.025" rpy="0 0 0" />
  </joint>

  <link name="base_link">
    <visual>
      <geometry>
        <box size="0.265 0.14 0.085" />
      </geometry>
      <material name="blue" />
    </visual>
    <collision>
      <geometry>
        <box size="0.265 0.14 0.085" />
      </geometry>
    </collision>
    <xacro:inertial_box mass="1" x="0.265" y="0.14" z="0.085">
      <origin xyz="0.0 0.0 0.0" rpy="0.0 0.0 0.0" />
    </xacro:inertial_box>
  </link>

  <!-- Macro for wheels -->
  <xacro:macro name="wheel" params="name_prefix x y">
    <joint name="${name_prefix}_wheel_joint" type="continuous">
      <parent link="base_link" />
      <child link="${name_prefix}_wheel_link" />
      <origin xyz="${x * 0.08} ${y * 0.10} -0.025" rpy="-${pi/2} -${pi/2} 0.0" />
      <axis xyz="0.0 0.0 1.0" />
    </joint>
    <link name="${name_prefix}_wheel_link">
      <visual>
        <geometry>
          <cylinder radius="0.05" length="0.038" />
        </geometry>
        <material name="red" />
      </visual>
      <collision>
        <geometry>
          <cylinder radius="0.05" length="0.038" />
        </geometry>
      </collision>
      <xacro:inertial_cylinder mass="1" length="0.038" radius="0.05">
        <origin xyz="0.0 0.0 0.0" rpy="0.0 0.0 0.0" />
      </xacro:inertial_cylinder>
    </link>
  </xacro:macro>

  <!-- Left front wheel -->
  <xacro:wheel name_prefix="lf" x="1" y="1" />

  <!-- Right front wheel -->
  <xacro:wheel name_prefix="rf" x="1" y="-1" />

  <!-- Left backend wheel -->
  <xacro:wheel name_prefix="lb" x="-1" y="1" />

  <!-- Right backend wheel -->
  <xacro:wheel name_prefix="rb" x="-1" y="-1" />

</robot>